<mujoco model="archer_l6y_gp100">
  <compiler angle="radian" />

  <asset>
    <mesh name="base_link" content_type="model/stl" file="base_link.STL" />
    <mesh name="link_1" content_type="model/stl" file="link_1.STL" />
    <mesh name="link_2" content_type="model/stl" file="link_2.STL" />
    <mesh name="link_3" content_type="model/stl" file="link_3.STL" />
    <mesh name="link_4" content_type="model/stl" file="link_4.STL" />
    <mesh name="link_5" content_type="model/stl" file="link_5.STL" />
    <mesh name="link_6" content_type="model/stl" file="link_6.STL" />
    <mesh name="gp100_base_link" content_type="model/stl" file="gp100_base_link.STL" />
    <mesh name="gp100_link_camera" content_type="model/stl" file="gp100_link_camera.STL" />
    <mesh name="gp100_link_2" content_type="model/stl" file="gp100_link_2.STL" />
    <mesh name="gp100_link_3" content_type="model/stl" file="gp100_link_3.STL" />
    <mesh name="gp100_link_1" content_type="model/stl" file="gp100_link_1.STL" />
    <mesh name="gp100_link_5" content_type="model/stl" file="gp100_link_5.STL" />
    <mesh name="gp100_link_6" content_type="model/stl" file="gp100_link_6.STL" />
    <mesh name="gp100_link_4" content_type="model/stl" file="gp100_link_4.STL" />
  </asset>

  <worldbody>
    <geom type="mesh" rgba="1 1 1 1" mesh="base_link" />
    <body name="link_1" pos="0 0 0.08355">
      <inertial pos="0.00884023 -0.0003974 0.0345724" quat="0.692552 0.669889 0.191379 -0.187069"
        mass="0.29593" diaginertia="0.000513613 0.000382445 0.000300442" />
      <joint name="joint_1" pos="0 0 0" axis="0 0 1" range="-2.8623 2.8623" actuatorfrcrange="-1 1" />
      <geom type="mesh" rgba="1 1 1 1" mesh="link_1" />
      <body name="link_2" pos="0.02 -0.0285 0.0555">
        <inertial pos="-0.00159885 0.0274031 0.133798"
          quat="0.999997 0.000210847 -0.00044992 0.00258668" mass="1.34359"
          diaginertia="0.0190563 0.0189042 0.000864312" />
        <joint name="joint_2" pos="0 0 0" axis="0 1 0" range="-2.0943 1.5707"
          actuatorfrcrange="-1 1" />
        <geom type="mesh" rgba="1 1 1 1" mesh="link_2" />
        <body name="link_3" pos="0 0 0.27">
          <inertial pos="-0.054542 0.0277058 0.146311"
            quat="0.99689 0.00229933 -0.0771506 0.0158967" mass="1.08626"
            diaginertia="0.0119831 0.0118262 0.00122099" />
          <joint name="joint_3" pos="0 0 0" axis="0 1 0" range="0 3.159" actuatorfrcrange="-1 1" />
          <geom type="mesh" rgba="1 1 1 1" mesh="link_3" />
          <body name="link_4" pos="-0.065 0 0.25">
            <inertial pos="-0.0463922 0.0283284 0.0449395"
              quat="0.0062881 0.921379 -0.00129265 0.388611" mass="0.53458"
              diaginertia="0.00129387 0.00109406 0.000430822" />
            <joint name="joint_4" pos="0 0 0" axis="0 1 0" range="-1.5707 1.5707"
              actuatorfrcrange="-1 1" />
            <geom type="mesh" rgba="1 1 1 1" mesh="link_4" />
            <body name="link_5" pos="-0.046 0.0285 0.065">
              <inertial pos="0.0408249 6.149e-05 0.00717093"
                quat="0.549825 0.422907 0.381068 0.611252" mass="0.38996"
                diaginertia="0.000229996 0.000225791 0.000156403" />
              <joint name="joint_5" pos="0 0 0" axis="-1 0 0" range="-1.5707 1.5707"
                actuatorfrcrange="-1 1" />
              <geom type="mesh" rgba="1 1 1 1" mesh="link_5" />
              <body name="link_6" pos="0.046 0 0.034">
                <inertial pos="0.00932162 -0.0133662 0.0436663"
                  quat="0.491955 0.839628 -0.208024 0.0986477" mass="1.08115"
                  diaginertia="0.00371162 0.00247209 0.00222616" />
                <joint name="joint_6" pos="0 0 0" axis="0 0 1" range="-3.1415 3.1415" />
                <geom type="mesh" rgba="1 1 1 1" mesh="link_6" />
                <geom quat="0.707105 0 -0.707108 0" type="mesh" rgba="1 1 1 1"
                  mesh="gp100_base_link" />
                <geom pos="-0.1201 0 0.0403996" quat="0.707105 0 -0.707108 0" type="mesh"
                  rgba="0.667 0.698 0.769 1" mesh="gp100_link_camera" />
                <body name="gripper_left_link_1" pos="-2.52648e-05 0.014 0.0721"
                  quat="0.707105 0 -0.707108 0">
                  <inertial pos="0.00299 0.02326 -5e-05" quat="0.996767 0 0 0.0803509"
                    mass="0.00595" diaginertia="2.73246e-06 1.46754e-06 1.3e-06" />
                  <joint name="gripper_left_joint_1" pos="0 0 0" axis="0 0 -1" range="0 1.52"
                    actuatorfrcrange="-5 5" />
                  <geom type="mesh" rgba="1 1 1 1" mesh="gp100_link_2" />
                  <body name="gripper_left_link_2" pos="0.0085108 0.04927 0">
                    <inertial pos="0.0255 0.00915 -0.00176"
                      quat="0.419839 0.419839 0.568977 0.568977" mass="0.0339"
                      diaginertia="1.36951e-05 1.36e-05 3.40486e-06" />
                    <joint name="gripper_left_joint_2" pos="0 0 0" axis="0 0 1" range="0 1.52"
                      actuatorfrcrange="-5 5" />
                    <geom type="mesh" rgba="1 1 1 1" mesh="gp100_link_3" />
                  </body>
                </body>
                <body name="gripper_left_helper_link" pos="-2.52118e-05 0.030604 0.057667"
                  quat="0.707105 0 -0.707108 0">
                  <inertial pos="0.00299 0.02326 -5e-05" quat="0.996767 0 0 0.0803509"
                    mass="0.00595" diaginertia="2.73246e-06 1.46754e-06 1.3e-06" />
                  <joint name="gripper_left_helper_joint" pos="0 0 0" axis="0 0 -1" range="0 1.52"
                    actuatorfrcrange="-5 5" />
                  <geom type="mesh" rgba="1 1 1 1" mesh="gp100_link_1" />
                </body>
                <body name="gripper_right_link_1" pos="-2.52648e-05 -0.014 0.0721"
                  quat="0.707105 0 -0.707108 0">
                  <inertial pos="0.00299 -0.02326 -5e-05" quat="0.996767 0 0 -0.0803509"
                    mass="0.00595" diaginertia="2.73246e-06 1.46754e-06 1.3e-06" />
                  <joint name="gripper_right_joint_1" pos="0 0 0" axis="0 0 1" range="0 1.52"
                    actuatorfrcrange="-5 5" />
                  <geom type="mesh" rgba="1 1 1 1" mesh="gp100_link_5" />
                  <body name="gripper_right_link_2" pos="0.0085108 -0.04927 0">
                    <inertial pos="0.0255 -0.00915 -0.00176"
                      quat="0.568977 0.568977 0.419839 0.419839" mass="0.0339"
                      diaginertia="1.36951e-05 1.36e-05 3.40486e-06" />
                    <joint name="gripper_right_joint_2" pos="0 0 0" axis="0 0 -1" range="0 1.52"
                      actuatorfrcrange="-5 5" />
                    <geom type="mesh" rgba="1 1 1 1" mesh="gp100_link_6" />
                  </body>
                </body>
                <body name="gripper_right_helper_link" pos="-2.52118e-05 -0.030604 0.057667"
                  quat="0.707105 0 -0.707108 0">
                  <inertial pos="0.00299 -0.02326 -5e-05" quat="0.996767 0 0 -0.0803509"
                    mass="0.00595" diaginertia="2.73246e-06 1.46754e-06 1.3e-06" />
                  <joint name="gripper_right_helper_joint" pos="0 0 0" axis="0 0 1" range="0 1.52"
                    actuatorfrcrange="-5 5" />
                  <geom type="mesh" rgba="1 1 1 1" mesh="gp100_link_4" />
                </body>
              </body>
            </body>
          </body>
        </body>
      </body>
    </body>
  </worldbody>
<equality>
    <!-- 
      solimp="0.99 0.99 0.01":
          The first two values near 1 mean the constraint stays "stiff" even at small constraint errors.
          The third value is the width parameter.
      solref="0.005 1":
          The first value is the time constant; smaller is stiffer (0.005s).
          The second value is the damping ratio; 1 is critical damping, preventing oscillation.
    -->
    <joint joint1="gripper_left_joint_1" joint2="gripper_left_joint_2" polycoef="0 1 0 0 0" solimp="0.99 0.99 0.01" solref="0.001 1"/>
    <joint joint1="gripper_left_joint_1" joint2="gripper_left_helper_joint" polycoef="0 1 0 0 0" solimp="0.99 0.99 0.01" solref="0.001 1"/>
    <joint joint1="gripper_left_joint_1" joint2="gripper_right_joint_1" polycoef="0 1 0 0 0" solimp="0.99 0.99 0.01" solref="0.001 1"/>
    <joint joint1="gripper_left_joint_1" joint2="gripper_right_joint_2" polycoef="0 1 0 0 0" solimp="0.99 0.99 0.01" solref="0.001 1"/>
    <joint joint1="gripper_left_joint_1" joint2="gripper_right_helper_joint" polycoef="0 1 0 0 0" solimp="0.99 0.99 0.01" solref="0.001 1"/>
</equality>
</mujoco>